<?xml version="1.0"?>
<robot xmlns:xacro="http://www.ros.org/wiki/xacro" name="body">
    <!-- Mesh from https://www.blendswap.com/blends/view/74733-->

    <xacro:macro name="body" params="prefix">

        <link name="${prefix}_torso_lift_link">
            <inertial>
                <origin rpy="0 0 0" xyz="-0.0013 -0.0009 0.2935" />
                <mass value="10.7796" />
                <inertia ixx="0.3354" ixy="0.0" ixz="-0.0162" iyy="0.3354" iyz="-0.0006" izz="0.0954" />
            </inertial>
            <visual>
                <origin rpy="0 0 0" xyz="0 0 0" />
                <geometry>
                    <mesh filename="package://fetch_simple_description/meshes/torso_lift_link.dae" />
                </geometry>
                <material name="">
                    <color rgba="1 1 1 1" />
                </material>
            </visual>
            <collision>
                <origin rpy="0 0 0" xyz="0 0 0" />
                <geometry>
                    <mesh filename="package://fetch_simple_description/meshes/torso_lift_link_collision.STL" />
                </geometry>
            </collision>
        </link>

        <joint name="${prefix}_torso_lift_joint" type="prismatic">
            <origin rpy="-6.123E-17 0 0" xyz="-0.086875 0 0.37743" />
            <parent link="${prefix}_base_link" />
            <child link="${prefix}_torso_lift_link" />
            <axis xyz="0 0 1" />
            <limit effort="450.0" lower="0" upper="0.38615" velocity="0.1" />
            <dynamics damping="100.0" />
        </joint>

        <transmission name="${prefix}_torso_lift_joint_tran">
            <type>transmission_interface/SimpleTransmission</type>
            <joint name="${prefix}_torso_lift_joint">
                <hardwareInterface>EffortJointInterface</hardwareInterface>
            </joint>
            <actuator name="${prefix}_torso_lift_joint_motor">
                <hardwareInterface>EffortJointInterface</hardwareInterface>
                <mechanicalReduction>1</mechanicalReduction>
            </actuator>
        </transmission>


        <link name="${prefix}_bellows_link">
            <inertial>
                <origin rpy="0 0 0" xyz="0.0191320000286228 -1.67219873481315E-16 -0.134861625443387" />
                <mass value="0.169374038216602" />
                <inertia ixx="0.00331159128762117" ixy="-8.9230964321455E-18" ixz="-5.38622201018293E-08" iyy="0.00174447292786627" iyz="-8.06964979976371E-17" izz="0.00169417568121457" />
            </inertial>
            <visual>
                <origin rpy="0 0 0" xyz="0 0 0" />
                <geometry>
                    <mesh filename="package://fetch_simple_description/meshes/bellows_link.STL" />
                </geometry>
                <material name="">
                    <color rgba="0 0 0 1" />
                </material>
            </visual>
            <collision>
            <origin rpy="0 0 0" xyz="0 0 0" />
            <geometry>
                <mesh filename="package://fetch_simple_description/meshes/bellows_link_collision.STL" />
            </geometry>
            </collision>
        </link>


        <joint name="${prefix}_bellows_joint" type="prismatic">
            <origin rpy="0 0 0" xyz="0 0 0" />
            <parent link="${prefix}_torso_lift_link" />
            <child link="${prefix}_bellows_link" />
            <axis xyz="0 0 1" />
            <limit effort="5.0" lower="0" upper="0.4" velocity="0.1" />
        </joint>

        <transmission name="${prefix}_bellows_joint_tran">
            <type>transmission_interface/SimpleTransmission</type>
            <joint name="${prefix}_bellows_joint">
                <hardwareInterface>EffortJointInterface</hardwareInterface>
            </joint>
            <actuator name="${prefix}_bellows_joint_motor">
                <hardwareInterface>EffortJointInterface</hardwareInterface>
                <mechanicalReduction>1</mechanicalReduction>
            </actuator>
        </transmission>

        <link name="${prefix}_bellows_link2">
            <inertial>
                <origin rpy="0 0 0" xyz="0.0191320000286228 -1.67219873481315E-16 -0.134861625443387" />
                <mass value="0.169374038216602" />
                <inertia ixx="0.00331159128762117" ixy="-8.9230964321455E-18" ixz="-5.38622201018293E-08" iyy="0.00174447292786627" iyz="-8.06964979976371E-17" izz="0.00169417568121457" />
            </inertial>
            <visual>
                <origin rpy="0 0 0" xyz="0 0 0" />
                <geometry>
                    <mesh filename="package://fetch_simple_description/meshes/bellows_link.STL" />
                </geometry>
                <material name="">
                    <color rgba="0 0 0 1" />
                </material>
            </visual>
            <collision>
                <origin rpy="0 0 0" xyz="0 0 0" />
                <geometry>
                    <mesh filename="package://fetch_simple_description/meshes/bellows_link_collision.STL" />
                </geometry>
            </collision>
        </link>

        <joint name="${prefix}_bellows_joint2" type="prismatic">
            <origin rpy="0 0 3.1415927" xyz="-0.14 0 0" />
            <parent link="${prefix}_torso_lift_link" />
            <child link="${prefix}_bellows_link2" />
            <axis xyz="0 0 1" />
            <limit effort="5.0" lower="0" upper="0.4" velocity="0.1" />
        </joint>


        <link name="${prefix}_estop_link">
            <inertial>
                <origin rpy="0 0 0" xyz="0.002434512737072 -0.00330608315239905 0.00665139196650039" />
                <mass value="0.00196130439134723" />
                <inertia ixx="3.02810026604417E-07" ixy="-1.5862023118056E-08" ixz="3.16561396557437E-08" iyy="2.93322917127605E-07" iyz="-4.28833522751273E-08" izz="2.28513272627183E-07" />
            </inertial>
            <visual>
                <origin rpy="0 0 0" xyz="0 0 0" />
                <geometry>
                    <mesh filename="package://fetch_simple_description/meshes/estop_link.dae" />
                </geometry>
                <material name="">
                    <color rgba="0.8 0 0 1" />
                </material>
            </visual>
            <collision>
                <origin rpy="0 0 0" xyz="0 0 0" />
                <geometry>
                    <mesh filename="package://fetch_simple_description/meshes/estop_link.STL" />
                </geometry>
            </collision>
        </link>

        <joint name="${prefix}_estop_joint" type="fixed">
            <origin rpy="1.5708 0 0" xyz="-0.12465 0.23892 0.31127" />
            <parent link="${prefix}_base_link" />
            <child link="${prefix}_estop_link" />
        <axis xyz="0 0 0" />
        </joint>

        <link name="${prefix}_laser_link">
            <inertial>
                <origin rpy="0 0 0" xyz="-0.0306228970175641 0.0007091682908278 0.0551974119471302" />
                <mass value="0.00833634573995571" />
                <inertia ixx="1.01866461240801E-06" ixy="-5.88447626567756E-08" ixz="7.83857244757914E-08" iyy="5.10039589974707E-07" iyz="-7.12664289617235E-09" izz="1.28270671527309E-06" />
            </inertial>
            <visual>
                <origin rpy="0 0 0" xyz="0 0 0" />
                <geometry>
                    <mesh filename="package://fetch_simple_description/meshes/laser_link.STL" />
                </geometry>
                <material name="">
                    <color rgba="0.792156862745098 0.819607843137255 0.933333333333333 1" />
                </material>
            </visual>
            <collision>
                <origin rpy="0 0 0" xyz="0 0 0" />
                <geometry>
                    <mesh filename="package://fetch_simple_description/meshes/laser_link.STL" />
                </geometry>
            </collision>
        </link>

        <joint name="${prefix}_laser_joint" type="fixed">
            <origin rpy="3.14159265359 0 0" xyz="0.235 0 0.2878" />
            <parent link="${prefix}_base_link" />
            <child link="${prefix}_laser_link" />
            <axis xyz="0 0 0" />
        </joint>

        <link name="${prefix}_torso_fixed_link">
            <inertial>
                <origin rpy="0 0 0" xyz="-0.0722 0.0057 0.2656" />
                <mass value="13.2775" />
                <inertia ixx="0.3861" ixy="0.0015" ixz="-0.0102" iyy="0.3388" iyz="0.0117" izz="0.1018" />
            </inertial>
            <visual>
                <origin rpy="0 0 0" xyz="0 0 0" />
                <geometry>
                <mesh filename="package://fetch_simple_description/meshes/torso_fixed_link.dae" />
                </geometry>
                <material name="">
                <color rgba="0.086 0.506 0.767 1" />
                </material>
            </visual>
            <collision>
                <origin rpy="0 0 0" xyz="0 0 0" />
                <geometry>
                    <mesh filename="package://fetch_simple_description/meshes/torso_fixed_link.STL" />
                </geometry>
            </collision>
        </link>

        <joint name="${prefix}_torso_fixed_joint" type="fixed">
            <origin rpy="-6.12303176911189E-17 0 0" xyz="-0.086875 0 0.377425" />
            <parent link="${prefix}_base_link" />
            <child link="${prefix}_torso_fixed_link" />
            <axis xyz="0 1 0" />
        </joint>


    </xacro:macro>

</robot>