<!-- ======================================================
    Copyright UWARL (UW Mechanical and Control Lab).
    (This file is based on the v36 URDF Fusion Model imported / modified by Jack.)
        
    Author      :: Jack (Jianxiang) Xu
        Contacts    : j337xu@uwaterloo.ca
        Last edits  : Jun 13, 2022
        
    TODO:
    - [ ] mass and inertial parameters check and configure
====================================================== -->

<mujocoinclude> 

    <!-- SUMMIT -->
    <body name="smt/base_link" childclass="summit" pos="0 0 0">
        <!-- === BASE LINK === === === === -->
        <!-- mobile body -->
        <inertial                                                              pos="0 0 0.37" mass="100" diaginertia="0.1 0.1 0.1" />
        <geom name="smt/viz/base_link"                      class="summit/viz" mesh="base_link_summit"/>
        <!-- <geom name="smt/col/base_link"                      class="summit/col" mesh="base_link_summit"/> -->
        <!-- Simplified the collision into boxes + arm rest -->
        <geom name="smt/col/base_link/box_body"             class="summit/col" pos="0 0 0.42" size="0.24 0.32 0.16" type="box"/>
        <geom name="smt/col/base_link/arm_rest"             class="summit/col" pos="0 0.098 0.55" quat="0.5 0.5 -0.5 -0.5" mesh="arm_rest"/>
        <geom name="smt/col/base_link/cylinder_lidar"       class="summit/col" pos="0.246 0.362 0.313" size="0.06 0.044" type="cylinder"/>

        <!-- world placement -->
        <joint name="smt/world_x" armature="0.0001" axis="1 0 0" damping="1e+11" pos="0 0 0" type="slide"></joint>
        <joint name="smt/world_y" armature="0.0001" axis="0 1 0" damping="1e+11" pos="0 0 0" type="slide"></joint>
        <joint name="smt/world_z" armature="0.0001" axis="0 0 1" damping="1e+0"  pos="0 0 0" type="slide"></joint>

        <!-- control summit base -->
        <joint name="smt/pose/x"                            type="slide" pos="0 0 0" axis="1 0 0" limited="true" range="-1 1" damping="15000"/>
        <joint name="smt/pose/y"                            type="slide" pos="0 0 0" axis="0 1 0" limited="true" range="-1 1" damping="15000"/>
        <joint name="smt/orie/z"                            type="hinge" pos="0 0 0" axis="0 0 1" limited="true" range="-3.14 3.14" damping="10000"/>

        <!-- === whl LINK === === === === -->
        <!-- Mobile whls -->
        <body name="smt/whl/LF_link" pos="0 0 0">
            <geom name="smt/viz/whl/LF"                    class="summit/viz" mesh="mecanum_LF_1"/>
            <geom name="smt/col/whl/LF_cylinder"           class="summit/col" pos="-0.220 0.222 0.128" quat="0.707107 0 0.707106 0" size="0.13 0.05" type="cylinder"/>
            <inertial                                                         pos="-0.220 0.222 0.128" mass="10.0" diaginertia="0.04411 0.02467 0.02467"/>
            <joint name="smt/whl_LF"                       class="summit/whl" pos="-0.264 0.222 0.128"/>
        </body>
        <body name="smt/whl/LR_link" pos="0 0 0">
            <geom name="smt/viz/whl/LR"                    class="summit/viz" mesh="mecanum_LR_1"/>
            <geom name="smt/col/whl/LR_cylinder"           class="summit/col" pos="-0.220 -0.223 0.128" quat="0.707107 0 0.707106 0" size="0.13 0.05" type="cylinder"/>
            <inertial                                                         pos="-0.220 -0.223 0.128" mass="10.0" diaginertia="0.04411 0.02467 0.02467"/>
            <joint name="smt/whl_LR"                       class="summit/whl" pos="-0.264 -0.223 0.128"/>
        </body>
        <body name="smt/whl/RF_link" pos="0 0 0">
            <geom name="smt/viz/whl/RF"                   class="summit/viz" mesh="mecanum_RF_1"/>
            <geom name="smt/col/whl/RF_cylinder"          class="summit/col" pos="0.220 0.222 0.128" quat="0.707107 0 0.707106 0" size="0.13 0.05" type="cylinder"/>
            <inertial                                                        pos="0.220 0.222 0.128" mass="10.0" diaginertia="0.04411 0.02467 0.02467"/>
            <joint name="smt/whl_RF"                      class="summit/whl" pos="0.264 0.222 0.128"/>
        </body>
        <body name="smt/whl/RR_link" pos="0 0 0">
            <geom name="smt/viz/whl/RR"                   class="summit/viz" mesh="mecanum_RR_1"/>
            <geom name="smt/col/whl/RR_cylinder"          class="summit/col" pos="0.220 -0.223 0.128" quat="0.707107 0 0.707106 0" size="0.13 0.05" type="cylinder"/>
            <inertial                                                        pos="0.220 -0.223 0.128" mass="10.0" diaginertia="0.04411 0.02467 0.02467"/>
            <joint name="smt/whl_RR"                      class="summit/whl" pos="0.264 -0.223 0.128"/>
        </body>

        <!-- === WAM 7DOF HAND LINK === === === === -->
        <!-- Place WAM Module Here -->
        <body name="wam_7dof_bhand" pos="0 0.14 0.405" quat="0.707 0 0 0.707">
            <include file="../components/include_wam_7dof_wam_bhand_Chain.xml"/>
        </body>
    </body>

</mujocoinclude>
