<!-- ======================================================
    Copyright UWARL (UW Mechanical and Control Lab).
    (This file is based on a Forklift Model imported / modified by Arnab.)
        
    Author      :: Arnab Joardar
        Contacts    : ajoardar@uwaterloo.ca
        Last edits  : Jul 3, 2024
        
    TODO:
    - 
====================================================== -->

<mujocoinclude> 

    <!-- Fetch -->
    <body name="fetch/base_link" pos="0 0 0">
        <!-- === BASE LINK === === === === -->
        <!-- mobile body -->
        <inertial                                       pos="-0.0036 0.0 0.0014" mass="70.1294" 
                                                        fullinertia="1.225 1.2853 0.987 0.0099 0.0062 -0.0034" />
        <geom name="fetch/viz/base_link"                class="fetch/body/viz" mesh="base_link"/>

        <!-- Simplified the collision into boxes -->
        <geom name="fetch/col/base_link/box_body"       class="fetch/col" mesh="base_link_collision"/>

        <!-- world placement -->
        <joint name="fetch/world_x" armature="0.0001" axis="0 1 0" damping="1e+11" pos="0 0 0" type="slide"></joint>
        <joint name="fetch/world_y" armature="0.0001" axis="-1 0 0" damping="1e+11" pos="0 0 0" type="slide"></joint>
        <joint name="fetch/world_z" armature="0.0001" axis="0 0 1" damping="1e+0"  pos="0 0 0" type="slide"></joint>

        <!-- control summit base -->
        <joint name="fetch/pose/x"                      type="slide" pos="0 0 0.4" axis="0 1 0"  damping="15"/>
        <joint name="fetch/pose/y"                      type="slide" pos="0 0 0.4" axis="-1 0 0"  damping="15"/>
        <joint name="fetch/orie/z"                      type="hinge" pos="0 0 0.4" axis="0 0 1"  damping="10"/>

        <!-- === whl LINK === === === === -->
        <!-- Left Wheel -->
        <body name="fetch/whl/L_link" pos="0.0012914 0.18738 0.055325" quat="1 0 0 0">
            <geom name="fetch/viz/L_whl"                class="fetch/whl/viz" mesh="l_wheel_link"/>
            <geom name="fetch/col/L_whl"                class="fetch/col" mesh="l_wheel_link_collision"/>
            <inertial                                   pos="0 0 0" mass="4.3542" diaginertia="0.0045 0.005 0.0045"/>
            <joint name="fetch/L_whl"                   class="fetch/whl" pos="0 0 0"/>
        </body>

        <!-- Right Wheel -->
        <body name="fetch/whl/R_link" pos="0.0012914 -0.18738 0.055325" quat="1 0 0 0">
            <geom name="fetch/viz/R_whl"                class="fetch/whl/viz" mesh="r_wheel_link"/>
            <geom name="fetch/col/R_whl"                class="fetch/col" mesh="r_wheel_link_collision"/>
            <inertial                                   pos="0 0 0" mass="4.3542" diaginertia="0.0045 0.005 0.0045"/>
            <joint name="fetch/R_whl"                   class="fetch/whl" pos="0 0 0"/>
        </body>

        <!-- === Torso-Lift Link === -->
        <body name="fetch/torso_lift_link" pos="-0.086875 0 0.37743" quat="1 0 0 0">
            <geom name="fetch/viz/torso_lift_link"      class="fetch/torso_lift_link/viz" mesh="torso_lift_link"/>
            <geom name="fetch/col/torso_lift_link"      class="fetch/col" mesh="torso_lift_link_collision"/>
            <inertial                                   pos="-0.0013 -0.0009 0.2935" mass="10.7796" fullinertia="0.3354 0.3354 0.0954 0 -0.0162 -0.0006"/>
            <joint name="fetch/torso_lift"              class="fetch/torso" pos="0 0 0"/>
            
            <!-- === Bellows Link === -->
            <body name="fetch/bellows_link" pos="0 0 0" quat="1 0 0 0">
                <geom name="fetch/viz/bellows_link"     class="fetch/bellows_link/viz" mesh="bellows_link"/>
                <geom name="fetch/col/bellows_link"     class="fetch/col" mesh="bellows_link_collision"/>
                <inertial                               pos="0.0191320000286228 0 -0.134861625443387" mass="0.169374038216602" 
                                                        fullinertia="0.00331159128762117 0.00174447292786627 0.00169417568121457 0 0 0"/>
                <joint name="fetch/bellows"        class="fetch/bellows" pos="0 0 0"/>                
            </body>

            <!-- === Bellows 2 Link === -->
            <body name="fetch/bellows_2_link" pos="0 0 0" quat="1 0 0 0">
                <geom name="fetch/viz/bellows_2_link"   class="fetch/bellows_2_link/viz" mesh="bellows_link"/>
                <geom name="fetch/col/bellows_2_link"   class="fetch/col" mesh="bellows_link_collision"/>
                <inertial                               pos="0.0191320000286228 0 -0.134861625443387" mass="0.169374038216602" 
                                                        fullinertia="0.00331159128762117 0.00174447292786627 0.00169417568121457 0 0 0"/>
            </body>

            <!-- === Head Pan Link === -->
            <body name="fetch/head_pan_link" pos="0.053125 0 0.603001417713939" quat="1 0 0 0">
                <geom name="fetch/viz/head_pan_link"    class="fetch/head_pan_link/viz" mesh="head_pan_link"/>
                <geom name="fetch/col/head_pan_link"    class="fetch/col" mesh="head_pan_link_collision"/>
                <inertial                               pos="0.0321 0.0161 0.0390" mass="2.2556" 
                                                        fullinertia="0.0129 0.0095 0.0184 0.0002 0.0007 0"/>
                <joint name="fetch/head_pan"       class="fetch/head_pan" pos="0 0 0"/>

                <!-- === Head Tilt Link === -->
                <body name="fetch/head_tilt_link" pos="0.14253 0 0.057999" quat="1 0 0 0">
                    <geom name="fetch/viz/head_tilt_link"   class="fetch/head_tilt_link/viz" mesh="head_tilt_link"/>
                    <geom name="fetch/col/head_tilt_link"   class="fetch/col" mesh="head_tilt_link_collision"/>
                    <inertial                               pos="0.0081 0.0025 0.0113" mass="0.9087" 
                                                            fullinertia="0.0061 0.0014 0.0061 0 0.0002 -0.0001"/>
                    <joint name="fetch/head_tilt"      class="fetch/head_tilt" pos="0 0 0"/>
                </body>
            </body>

            <!-- === Shoulder Pan Link === -->
            <body name="fetch/shoulder_pan_link" pos="0.119525 0 0.34858" quat="1 0 0 0">
                <geom name="fetch/viz/shoulder_pan_link"    class="fetch/shoulder_pan_link/viz" mesh="shoulder_pan_link"/>
                <geom name="fetch/col/shoulder_pan_link"    class="fetch/col" mesh="shoulder_pan_link_collision"/>
                <inertial                                   pos="0.0927 -0.0056 0.0564" mass="2.5587" 
                                                            fullinertia="0.0043 0.0087 0.0087 -0.0001 0.0001 -0.0001"/>
                <joint name="fetch/shoulder_pan"       class="fetch/shoulder_pan" pos="0 0 0"/>

                <!-- === Shoulder Lift Link === -->
                <body name="fetch/shoulder_lift_link" pos="0.117 0 0.06" quat="1 0 0 0">
                    <geom name="fetch/viz/shoulder_lift_link"   class="fetch/shoulder_lift_link/viz" mesh="shoulder_lift_link"/>
                    <geom name="fetch/col/shoulder_lift_link"   class="fetch/col" mesh="shoulder_lift_link_collision"/>
                    <inertial                                   pos="0.1432 0.0072 -0.0001" mass="2.6615" 
                                                                fullinertia="0.0028 0.0111 0.0112 -0.0021 0 0"/>
                    <joint name="fetch/shoulder_lift"      class="fetch/shoulder_lift" pos="0 0 0"/>

                    <!-- === Upper-arm Roll Link === -->
                    <body name="fetch/upper_arm_roll_link" pos="0.219 0 0" quat="1 0 0 0">
                        <geom name="fetch/viz/upper_arm_roll_link"  class="fetch/upper_arm_roll_link/viz" mesh="upperarm_roll_link"/>
                        <geom name="fetch/col/upper_arm_roll_link"  class="fetch/col" mesh="upperarm_roll_link_collision"/>
                        <inertial                                   pos="0.1165 0.0014 0" mass="2.3311" 
                                                                    fullinertia="0.0019 0.0045 0.0047 -0.0001 0 0"/>
                        <joint name="fetch/upper_arm_roll"          class="fetch/upper_arm_roll" pos="0 0 0"/>
                    </body>
                </body>
            </body>
        </body>

        <!-- === E-Stop Link === -->
        <body name="fetch/e_stop_link" pos="-0.12465 0.23892 0.31127" euler="1.5708 0 0">
            <geom name="fetch/viz/e_stop_link"          class="fetch/e_stop_link/viz" mesh="estop_link"/>
            <geom name="fetch/col/e_stop_link"          class="fetch/col" mesh="estop_link_collision"/>
            <inertial                                   pos="0.002434512737072 -0.00330608315239905 0.00665139196650039" mass="0.00196130439134723" 
                                                        fullinertia="3.02810026604417E-07 2.93322917127605E-07 2.28513272627183E-07 
                                                                     -1.5862023118056E-08 3.16561396557437E-08 -4.28833522751273E-08"/>
        </body>

        <!-- === Laser Link === -->
        <body name="fetch/laser_link" pos="0.235 0 0.2878" euler="3.14159265359 0 0">
            <geom name="fetch/viz/laser_link"           class="fetch/laser_link/viz" mesh="laser_link"/>
            <geom name="fetch/col/laser_link"           class="fetch/col" mesh="laser_link_collision"/>
            <inertial                                   pos="-0.0306228970175641 0.0007091682908278 0.0551974119471302" mass="0.00833634573995571" 
                                                        fullinertia="1.01866461240801E-06 5.10039589974707E-07 1.28270671527309E-06 
                                                                     -5.88447626567756E-08 7.83857244757914E-08 -7.12664289617235E-09"/>
        </body>

        <!-- === Torso Fixed Link === -->
        <body name="fetch/torso_fixed_link" pos="0.235 0 0.2878" euler="3.14159265359 0 0">
            <geom name="fetch/viz/torso_fixed_link"     class="fetch/torso_fixed/viz" mesh="torso_fixed_link"/>
            <geom name="fetch/col/torso_fixed_link"     class="fetch/col" mesh="torso_fixed_link_collision"/>
            <inertial                                   pos="-0.0306228970175641 0.0007091682908278 0.0551974119471302" mass="0.00833634573995571" 
                                                        fullinertia="1.01866461240801E-06 5.10039589974707E-07 1.28270671527309E-06 
                                                             -5.88447626567756E-08 7.83857244757914E-08 -7.12664289617235E-09"/>
        </body>

    </body>
        
        

</mujocoinclude>
