<!-- ======================================================
    This file is part of modified version based on the official MuJoCo WAM model.
    Copyright UWARL (UW Mechanical and Control Lab).
    
    Model       :: WAM Arm from Barrett technologies
        Source      : https://github.com/jhu-lcsr/barrett_model
        Downloaded  : Oct 10, 2015
        
    Mujoco      :: Advanced physics simulation engine
        Source      : www.roboti.us
        Version     : 1.31

    Original    :: Vikash kumar
        Source      : https://roboti.us/forum/index.php?resources/wam-and-barrett-hand.20/
        Downloaded  : Jun 13, 2022
        Contacts    : kumar@roboti.us
        
    Author      :: Jack (Jianxiang) Xu
        Contacts    : j337xu@uwaterloo.ca
        Last edits  : Jun 13, 2022
    
    Spec        :: WAM Inertial Spec (*1)
        Source      : https://web.barrett.com/support/WAM_Documentation/WAM_InertialSpecifications_AC-02.pdf
        Correction  : Jack @ Jun 20, 2022
        
    Spec        :: WAM Joint Range Spec (*2)
        Source      : https://support.barrett.com/wiki/WAM/KinematicsJointRangesConversionFactors
        Correction  : Jack @ Jun 22, 2022
        
    Spec        :: WAM Torque Sensor Spec (*3)
        Source      : https://web.barrett.com/supportFiles/wikiFiles/B4066Documentation.PDF
        Correction  : Jack @ Jun 22, 2022
    
    Spec        :: Intel L515 (*4)
        Source      : https://dev.intelrealsense.com/docs/lidar-camera-l515-datasheet
        Correction  : Jack @ Aug 05, 2022
        
    Updates:
        - [June 22, 2022] mass and inertial parameters re-populated based on (*1)
        - [June 22, 2022] range limits revised based on (*2)
        - [June 22, 2022] [IMPORTANT] T-S Sensor Plate has been added!!!
        - [June 23, 2022] fullinertia matrix (based on spec *1, *3)
        - [June 24, 2022] ZED Camera / Intel Realsense Eye on forearm
        - [ ] TODO: We need to calibrate / measure the damping / friction values
====================================================== -->

<mujocoinclude>

    <!-- WAM -->
    <body name="wam/base_link" childclass="wam" pos="0 0 0">
        <body name="wam/base" childclass="wam" pos="0 0 0">
            <!-- ### Inertial Ref: (*1, pg.10) unit: [m, kg, kg * m^2] 
                Note: 
                    - we have to offset the stl model frame to the inertial frame in doc
                    - pos = <z, x, y> + <0,0,0.346>
                    - **the axis should be based on the orientation notation at the bottom left corner
            -->
            <inertial   pos="-0.14071720 -0.02017671 0.07995294" mass="9.97059584" fullinertia="0.11760385 0.10916849 0.18294303 0.02557874 0.00161433 0.00640270" /> 
            <geom       class="wam/viz" mesh="base_link_fine"/>
            <geom       class="wam/col" mesh="base_link_convex"/>
        </body>

        <body name="wam/shoulder_yaw_link" pos="0 0 0.346">
            <!-- ### Inertial Ref: (*1, pg.12) unit: [m, kg, kg * m^2] 
                Note:
                    - frame correction to the stl: <x, z, -y>
            -->
            <inertial               pos="-0.00443422 -0.00066489 -0.12189039" mass="10.76768767" fullinertia="0.13488033 0.09046330 0.11328369 -0.00012485 0.00213041 -0.00068555" />
            <joint name="wam/J1"    range="-2.6 2.6" damping="1000" frictionloss="1000"/>
            <geom                   class="wam/shoulder_yaw_link/viz" mesh="shoulder_link_fine"/>
            <geom                   class="wam/col" mesh="shoulder_link_convex_decomposition_p1"/>
            <geom                   class="wam/col" mesh="shoulder_link_convex_decomposition_p2"/>
            <geom                   class="wam/col" mesh="shoulder_link_convex_decomposition_p3"/>
            
            <body name="wam/shoulder_pitch_link" pos="0 0 0" quat="0.707107 -0.707107 0 0"> 
                <!-- ### Inertial Ref: (*1, pg.14) unit: [m, kg, kg * m^2] 
                    Note:
                        - frame correction to the stl: <x, -z, y>
                -->
                <!-- <body name="wam/shoulder_pitch_link" pos="0 0 0"> -->
                <inertial               pos="-0.00236983 -0.01542114 0.03105614" mass="3.8749" fullinertia="0.02140958 0.01558906 0.01377875 -0.00002461 0.00027172 0.00181920" />
                <joint name="wam/J2"    range="-2.0 2.0" damping="1000" frictionloss="1000"/>
                <geom                   class="wam/shoulder_pitch_link/viz" mesh="shoulder_pitch_link_fine"/>
                <geom                   class="wam/col" mesh="shoulder_pitch_link_convex"/>
                
                <body name="wam/upper_arm_link" pos="0 0 0" quat="0.707107 0.707107 0 0">
                    <!-- ### Inertial Ref: (*1, pg.16) unit: [m, kg, kg * m^2] 
                        Note: 
                            - we have to offset the stl model frame to the inertial frame in doc
                            - pos = <0.045, 0, 0.55> - <0.03825858, 0.00003309, 0.20750770>
                            - frame correction to the stl: <x, -z, -y>
                    -->
                    <!-- <body name="wam/upper_arm_link" pos="0 0 0"> -->
                    <inertial               pos="0.00674142 -0.00003309 0.3424923" mass="1.8028141" fullinertia="0.05911077 0.05927043 0.00324550 -0.00000738 0.00249612 -0.00001767" />
                    <joint name="wam/J3"    range="-2.8 2.8" damping="500" frictionloss="1000"/>
                    <geom                   class="wam/upper_arm_link/viz" mesh="upper_arm_link_fine"/>
                    <geom                   class="wam/col" mesh="upper_arm_link_convex_decomposition_p1"/>
                    <geom                   class="wam/col" mesh="upper_arm_link_convex_decomposition_p2"/>
                    
                    <body name="wam/forearm_link" pos="0.045 0 0.55" quat="0.707107 -0.707107 0 0">
                        <!-- ### Inertial Ref: (*1, pg.22) unit: [m, kg, kg * m^2]
                            [ Elbow + WristBase (7DOF) ]
                            Note: 
                                - 4DOF has a different attribute here
                                - we have to offset the stl model frame (at the elbow joint) to the inertial frame in doc (z4 aligned with central axis of the elbow)
                                - pos = <0.00498512 -0.1327162 -0.00022942> - <0.045, 0, 0>
                                - frame correction to the stl: <x, -z, y>
                        -->
                        <!-- <body name="wam/forearm_link" pos="0.045 0 0.55"> -->
                        <inertial               pos="-0.04001488 -0.1327162 -0.00022942" mass="2.40016804" fullinertia="0.01491672 0.00294463 0.01482922 0.00150604 0.00001741 0.00002109" />
                        <joint name="wam/J4"    range="-0.9 3.1" damping="100" frictionloss="1000"/>
                        <geom                   class="wam/elbow_link/viz" mesh="elbow_link_fine"/>
                        <geom                   class="wam/col" mesh="elbow_link_convex"/>
                        <geom                   class="wam/fore_arm_link/viz" mesh="forearm_link_fine" pos="-.045 -0.0730 0" euler="1.57 0 0"/>
                        <geom                   class="wam/col" mesh="forearm_link_convex_decomposition_p1" pos="-0.045 -0.0730 0" euler="1.57 0 0"/>
                        <geom                   class="wam/col" mesh="forearm_link_convex_decomposition_p2" pos="-0.045 -0.0730 0" euler="1.57 0 0"/>
                        
                        <!-- [Optional] ZED Camera on forearm link, TODO: uncertain for inertial params -->
                        <!-- <body name="wam/sensor/zed" pos="-0.18 -0.15 0" quat="0 0.707107 0 0.707107">
                            <inertial               pos="0 0 0.015" mass="0.124"/>
                            <geom                   class="wam/viz" mesh="zed"/>
                            <geom                   class="wam/col" mesh="zed_collision_mesh"/>
                            <camera name="camera/zed/R" pos="-0.06 0.03 0.042"  quat="0 0 -0.707107 0.707107" fovy="60"/>
                            <camera name="camera/zed/L" pos=" 0.06 0.03 0.042"  quat="0 0 -0.707107 0.707107" fovy="60"/>
                        </body> -->
                        
                        <body name="wam/wrist_yaw_link" pos="-0.045 -0.3 0" quat="0.707107 0.707107 0 0">
                            <!-- ### Inertial Ref: (*1, pg.24) unit: [m, kg, kg * m^2] 
                                Note:
                                    - frame correction to the stl: <x, z, -y>
                            -->
                            <!-- <body name="wam/wrist_yaw_link" pos="-0.045 -0.3 0"> -->
                            <inertial               pos="0.00008921 0.00435824 -0.00511217" mass="0.12376019" fullinertia="0.00005029 0.00006270 0.00007582 -0.00000005 -0.00000020 0.00000359" /> 
                            <joint name="wam/J5"    range="-4.8 1.3" damping="50" frictionloss="1000"/>
                            <geom                   class="wam/wrist_yaw_link/viz" mesh="wrist_yaw_link_fine"/>
                            <geom                   class="wam/col" mesh="wrist_yaw_link_convex_decomposition_p1"/>
                            <geom                   class="wam/col" mesh="wrist_yaw_link_convex_decomposition_p2"/>
                            
                            <body name="wam/wrist_pitch_link" pos="0 0 0" quat="0.707107 -0.707107 0 0">
                                <!-- ### Inertial Ref: (*1, pg.26) unit: [m, kg, kg * m^2] 
                                    Note:
                                        - frame correction to the stl: <x, -z, y>
                                -->
                                <!-- <body name="wam/wrist_pitch_link" pos="0 0 0" > -->
                                <inertial               pos="-0.00012262 -0.02468336 -0.01703194" mass="0.41797364" fullinertia="0.00055516 0.00045358 0.00024367 0.00000074 0.00000061 0.00004590" />
                                <joint name="wam/J6"    range="-1.6 1.6" damping="50" frictionloss="1000"/>
                                <geom                   class="wam/wrist_pitch_link/viz" mesh="wrist_pitch_link_fine"/>
                                <geom                   class="wam/col" mesh="wrist_pitch_link_convex_decomposition_p1"/>
                                <geom                   class="wam/col" mesh="wrist_pitch_link_convex_decomposition_p2"/>
                                <geom                   class="wam/col" mesh="wrist_pitch_link_convex_decomposition_p3"/>
                                
                                <body name="wam/wrist_palm_link" pos="0 0 0" quat="0.707107 0.707107 0 0">
                                    <!-- ### Inertial Ref: (*1, pg.14) unit: [m, kg, kg * m^2] 
                                        Note:
                                            - frame correction to the stl: <x, y, z + 0.055>
                                            - [Optional] We could neglect x,y components as if it is a disc
                                    -->
                                    <!-- <body name="wam/wrist_palm_link" pos="0 0 0"> -->
                                    <inertial               pos="-0.00007974 0.0001613 0.05176448" mass="0.06864753" fullinertia="0.00003773 0.00003806 0.00007408 -0.00000019 0.00000000 0.00000000" />
                                    <joint name="wam/J7"    range="-2.2 2.2" damping="10" frictionloss="1000"/>
                                    <geom                   class="wam/wrist_palm_link/viz" mesh="wrist_palm_link_fine"/>
                                    <geom                   class="wam/col" mesh="wrist_palm_link_convex"/>
                                    
                                    
                                    <!-- [Optional] Intel Lidar Camera (*4) -->
                                    <body name="wam/camera" pos="0 0.085 0.02">
                                        <inertial               pos="0 0 0.015" mass="0.095"/>
                                        <geom                   class="wam/viz" mesh="intel_realsense_l515"/>
                                        <geom                   class="wam/col" mesh="intel_realsense_l515_collision_mesh"/>
                                        <camera name="wam/camera/intel/rgb" quat="0 0 1 0" fovy="55"/><!-- quant=w x y z -->
                                    </body>
                                    
                                    <!-- ### T-S Sensor (*3) Ref: (*3) unit: [m, kg, kg * m^2] 
                                        Note:
                                            - [USER PARAMS] 0.06: mounting position z-axis depends on the actual measurements
                                            - No need for the collision mesh, as the disk size is think enough that can be negligible as if its an air gap
                                            - stl: generated from original CAD file [Unit Conversion: 1 g*mm^2 = 1e-9 kg*m^2]
                                            - frame correction to the stl: <x, z, y>
                                    -->
                                    <body name="wam/torque_sensor_link" pos="0 0 0.060" quat="0.707107 0.707107 0 0">
                                        <inertial               pos="0 0.0085 0" mass="0.133278" fullinertia="0.00007551 0.0001462 0.00007508 -7.002e-8 -1.199e-7 -5.37e-8" />
                                        <geom                   class="wam/torque_sensor_link/viz" mesh="torque_sensor_plate"/>
                                        
                                        <!-- ### WAM BHAND 
                                            Note:
                                                - [USER PARAMS] 0.01: mounting gap
                                        -->
                                        <body name="wam/bhand"  pos="0 0.01 0"  quat="0 0 0.707107 0.707107">
                                            <include file="../components/include_bhand_Chain.xml"/>
                                        </body>
                                    </body>
                                    
                                </body>
                            </body>
                        </body>
                    </body>
                </body>
            </body>
        </body>
    </body>
    <!-- END of WAM -->

</mujocoinclude>
