<mujoco model="smt_\base_link">
  <default>
    <default class="/">
      <default class="summit\body\viz"/>
    </default>
    <default class="smt_\front\camera\intel/"/>
    <default class="smt_\rear\camera\intel/"/>
    <default class="smt_\pole_link\camera\intel/"/>
    <default class="smt_\whl\LF_link/"/>
    <default class="smt_\whl\LR_link/"/>
  </default>
  <worldbody>
    <body name="smt_" pos="0 0 0">
      <inertial pos="0 0 0.37" mass="125" diaginertia="1.391 6.8529999999999998 6.125"/>
      <geom name="smt_\viz\\base_link" class="summit\body\viz" mesh="base_link_summit"/>
      <site name="//unnamed_site_0" class="site" pos="0 0.36199999999999999 0.373" quat="0 0 0.70710700000000004 0.70710700000000004"/>
      <body pos="0 0.36199999999999999 0.373" quat="0 0 0.70710700000000004 0.70710700000000004" name="smt_\front\camera\intel/">
        <body name="smt_\front\camera\intel/smt_\front\camera\intel">
          <inertial pos="0 0 0.014999999999999999" mass="0.095000000000000001"/>
          <geom name="smt_\front\camera\intel//unnamed_geom_0" class="smt_\front\camera\intel/wam\viz" mesh="smt_\front\camera\intel/intel_realsense_l515"/>
          <camera name="smt_\front\camera\intel/smt_\front\camera\intel\rgb" class="smt_\front\camera\intel/" fovy="55" pos="0 0 0" quat="0 0 1 0"/>
        </body>
      </body>
      <site name="//unnamed_site_1" class="site" pos="0 -0.73499999999999999" quat="0.70710700000000004 0.70710700000000004 0 0"/>
      <body pos="0 -0.73499999999999999" quat="0.70710700000000004 0.70710700000000004 0 0" name="smt_\rear\camera\intel/">
        <body name="smt_\rear\camera\intel/smt_\rear\camera\intel">
          <inertial pos="0 0 0.014999999999999999" mass="0.095000000000000001"/>
          <geom name="smt_\rear\camera\intel//unnamed_geom_0" class="smt_\rear\camera\intel/wam\viz" mesh="smt_\rear\camera\intel/intel_realsense_l515"/>
          <camera name="smt_\rear\camera\intel/smt_\rear\camera\intel\rgb" class="smt_\rear\camera\intel/" fovy="55" pos="0 0 0" quat="0 0 1 0"/>
        </body>
      </body>
      <body name="smt_\pole_link" pos="0 0.32000000000000001 1">
        <geom name="smt_\viz\pole_link" class="summit\wheel\viz" type="cylinder" size="0.0050000000000000001 0.41999999999999998"/>
        <site name="//unnamed_site_2" class="/" pos="0 0 0.44" quat="0.70710700000000004 0.70710700000000004 0 0"/>
        <body pos="0 0 0.44" quat="0.70710700000000004 0.70710700000000004 0 0" name="smt_\pole_link\camera\intel/">
          <body name="smt_\pole_link\camera\intel/smt_\pole_link\camera\intel">
            <inertial pos="0 0 0.014999999999999999" mass="0.095000000000000001"/>
            <geom name="smt_\pole_link\camera\intel//unnamed_geom_0" class="smt_\pole_link\camera\intel/wam\viz" mesh="smt_\pole_link\camera\intel/intel_realsense_l515"/>
            <camera name="smt_\pole_link\camera\intel/smt_\pole_link\camera\intel\rgb" class="smt_\pole_link\camera\intel/" fovy="90" pos="0 0 0" quat="0 0 1 0"/>
          </body>
        </body>
      </body>
      <geom name="smt_\col\\base_link\box_body" class="summit\col" type="box" size="0.23999999999999999 0.32000000000000001 0.16" pos="0 0 0.41999999999999998"/>
      <geom name="smt_\col\\base_link\arm_rest" class="summit\col" pos="0 0.098000000000000004 0.55000000000000004" quat="0.5 0.5 -0.5 -0.5" mesh="arm_rest"/>
      <geom name="smt_\col\\base_link\cylinder_lidar" class="summit\col" type="cylinder" size="0.059999999999999998 0.043999999999999997" pos="0.246 0.36199999999999999 0.313"/>
      <joint name="smt_\world_x" class="/" type="slide" pos="0 0 0" axis="0 1 0" armature="0.0001" damping="100000000000"/>
      <joint name="smt_\world_y" class="/" type="slide" pos="0 0 0" axis="-1 0 0" armature="0.0001" damping="100000000000"/>
      <joint name="smt_\world_z" class="/" type="slide" pos="0 0 0" axis="0 0 1" armature="0.0001" damping="1"/>
      <joint name="smt_\pose\x" class="/" type="slide" pos="0 0 0.40000000000000002" axis="0 1 0" damping="15"/>
      <joint name="smt_\pose\y" class="/" type="slide" pos="0 0 0.40000000000000002" axis="-1 0 0" damping="15"/>
      <joint name="smt_\orie\z" class="/" type="hinge" pos="0 0 0.40000000000000002" axis="0 0 1" damping="10"/>
      <site name="//unnamed_site_3" class="site" pos="-0.22 0.222 0.128" quat="0.70710700000000004 0 0.70710600000000001 0"/>
      <body pos="-0.22 0.222 0.128" quat="0.70710700000000004 0 0.70710600000000001 0" name="smt_\whl\LF_link/">
        <body name="smt_\whl\LF_link/smt_\whl\LF_link" pos="0 0 0">
          <geom name="smt_\whl\LF_link/smt_\viz\whl\LF" class="smt_\whl\LF_link/summit\wheel\viz" mesh="smt_\whl\LF_link/mecanum_LF_1"/>
          <geom name="smt_\whl\LF_link/smt_\viz\whl\LF_cylinder" class="smt_\whl\LF_link/summit\col" type="cylinder" size="0.13 0.050000000000000003" friction="0.0001 0.001 0.001"/>
          <inertial pos="0 0 0" mass="10" diaginertia="0.044110000000000003 0.024670000000000001 0.024670000000000001"/>
          <joint name="smt_\whl\LF_link/smt_\whl_LF" class="smt_\whl\LF_link/summit\whl" pos="0 0 0"/>
        </body>
      </body>
      <site name="//unnamed_site_4" class="site" pos="-0.22 -0.223 0.128" quat="0.70710700000000004 0 0.70710600000000001 0"/>
      <body pos="-0.22 -0.223 0.128" quat="0.70710700000000004 0 0.70710600000000001 0" name="smt_\whl\LR_link/">
        <body name="smt_\whl\LR_link/smt_\whl\LR_link" pos="0 0 0">
          <geom name="smt_\whl\LR_link/smt_\viz\whl\LR" class="smt_\whl\LR_link/summit\wheel\viz" mesh="smt_\whl\LR_link/mecanum_LR_1"/>
          <geom name="smt_\whl\LR_link/smt_\viz\whl\LR_cylinder" class="smt_\whl\LR_link/summit\col" type="cylinder" size="0.13 0.050000000000000003" friction="0.0001 0.001 0.001"/>
          <inertial pos="0 0 0" mass="10" diaginertia="0.044110000000000003 0.024670000000000001 0.024670000000000001"/>
          <joint name="smt_\whl\LR_link/smt_\whl_LR" class="smt_\whl\LR_link/summit\whl" pos="0 0 0"/>
        </body>
      </body>
    </body>
  </worldbody>
</mujoco>
