<!--
 * COPYRIGHT (C) 2010
 * RE2, INC.
 *
 * Author: RE2
 *
 * This file is a part of RobotModel, which was developed for the
 * DARPA ARM ROBOT Track C project.
 *
 * RobotModel is free software:
 * you can redistribute it and/or modify it under the terms of the GNU General
 * Public License as published by the Free Software Foundation, either version
 * 3 of the License, or (at your option) any later version.
 *
 * You should have received a copy of the GNU General Public License along
 * with this package.  If not, see <http://www.gnu.org/licenses/>.
 *
 * RE2, INC. disclaims all warranties with regard to this software, including
 * all implied warranties of merchantability and fitness, in no event shall
 * RE2, INC. be liable for any special, indirect or consequential damages or
 * any damages whatsoever resulting from loss of use, data or profits, whether
 * in an action of contract, negligence or other tortious action, arising out
 * of or in connection with the use or performance of this software.
-->

<robot xmlns:xacro="http://ros.org/wiki/xacro">

    <xacro:include filename="$(find waterloo_steel_description)/urdf/wam/hand.urdf.xacro"/>
    <xacro:include filename="$(find waterloo_steel_description)/urdf/wam/common.urdf.xacro"/>
    <xacro:property name="b" value="0.5"/>

    <xacro:property name="M_PI" value="3.1415926535897931"/>

    <!-- Upper arm macros -->
    <xacro:macro name="wam_base" params="prefix parent_link xyz rpy">
        <joint name="${prefix}/wam_fixed_joint" type="fixed">
            <parent link="${parent_link}"/>
            <child link="${prefix}/base_link"/>
            <origin xyz="${xyz}" rpy="${rpy}"/>
        </joint>
        <gazebo reference="${prefix}/wam_fixed_joint">
            <xacro:gz_joint/>
        </gazebo>

        <link name = "${prefix}/base_link">
            <inertial>
                <origin xyz="-0.14071720 -0.02017671 0.07995294" />
                <mass value="9.97059584" />
                <inertia
                    ixx="0.11760385"    ixy="0.02557874"    ixz="0.00161433"
                                        iyy="0.10916849"    iyz="0.00640270"
                                                            izz="0.18294303" />
            </inertial>
            <visual>
                <material name="WAMGrey">
                    <color rgba="0.7 0.7 0.7 0.0"/>
                </material>
                <geometry>
                    <mesh filename="${models_path}/meshes/meshes_wam/base_link_fine.stl"/>
                </geometry>
            </visual>
            <collision>
                <geometry>
                    <mesh filename="${models_path}/meshes/meshes_wam/base_link_convex.stl"/>
                </geometry>
            </collision>
        </link>
    </xacro:macro>

    <xacro:macro name="wam_shoulder_yaw" params="prefix">
        <joint name="${prefix}/base_yaw_joint" type="revolute">
            <parent link="${prefix}/base_link"/>
            <child link="${prefix}/shoulder_yaw_link"/>
            <origin xyz="0 0 0.346" rpy="0 0 0"/>
            <axis xyz="0 0 1"/>
            <limit effort="${60*4}" lower="${-148.97 * M_PI / 180.0}" upper="${148.97 * M_PI / 180.0}" velocity="2.0"/>
            <dynamics damping="${1.8*b}" friction="0"/>
        </joint>
        <gazebo reference="${prefix}/base_yaw_joint">
            <xacro:gz_joint/>
        </gazebo>
        <!-- <transmission name="${prefix}/base_yaw_trans">
            <type>transmission_interface/SimpleTransmission</type>
            <joint name="${prefix}/base_yaw_joint">
                <hardwareInterface>hardware_interface/VelocityJointInterface</hardwareInterface>
            </joint>
            <actuator name="${prefix}/base_yaw_motor">
                <mechanicalReduction>1</mechanicalReduction>
            </actuator>
        </transmission> -->

        <link name="${prefix}/shoulder_yaw_link" >
            <inertial>
                <origin xyz="-.00443422 -.00066489 -0.1289039 " />
                <mass value="${5*0.1}" /> <!-- Before, it was 10.76768767, now it is 5 from the Barett WAM spec pdf in the Mujoco simulator repo -->
                <inertia
                    ixx=".13488033"     ixy="-0.00012485"   ixz="0.00213041"
                                        iyy=".09046330"     iyz="-.00068555"
                                                            izz=".11328369" />
            </inertial>
            <visual>
                <material name="WAMGrey">
                    <color rgba="0.7 0.7 0.7 1.0"/>
                </material>
                <geometry>
                    <mesh filename="${models_path}/meshes/meshes_wam/shoulder_link_fine.stl"/>
                </geometry>
            </visual>
            <collision>
                <geometry>
                    <mesh filename="${models_path}/meshes/meshes_wam/shoulder_link_convex_decomposition_p1.stl"/>
                    <mesh filename="${models_path}/meshes/meshes_wam/shoulder_link_convex_decomposition_p2.stl"/>
                    <mesh filename="${models_path}/meshes/meshes_wam/shoulder_link_convex_decomposition_p3.stl"/>
                </geometry>
            </collision>
        </link>
    </xacro:macro>

    <xacro:macro name="wam_shoulder_pitch" params="prefix">
        <joint name="${prefix}/shoulder_pitch_joint" type="revolute">
            <parent link="${prefix}/shoulder_yaw_link"/>
            <child link="${prefix}/shoulder_pitch_link"/>
            <origin xyz="0 0 0" rpy="${-PI/2} 0 0"/>
            <axis xyz="0 0 1"/>
            <limit effort="${60*4}" lower="${-113.732 * M_PI / 180.0}" upper="${113.732 * M_PI / 180.0}" velocity="2.0"/>
            <dynamics damping="${0.5*b}" friction="0"/>
        </joint>
        <gazebo reference="${prefix}/shoulder_pitch_joint">
            <xacro:gz_joint/>
        </gazebo>
        <!-- <transmission name="${prefix}/shoulder_pitch_trans">
            <type>transmission_interface/SimpleTransmission</type>
            <joint name="${prefix}/shoulder_pitch_joint">
                <hardwareInterface>hardware_interface/VelocityJointInterface</hardwareInterface>
            </joint>
            <actuator name="${prefix}/shoulder_pitch_motor">
                <mechanicalReduction>1</mechanicalReduction>
            </actuator>
        </transmission> -->

        <link name="${prefix}/shoulder_pitch_link" >
            <visual>
                <material name="WAMGrey">
                    <color rgba="0.7 0.7 0.7 1.0"/>
                </material>
                <geometry>
                    <mesh filename="${models_path}/meshes/meshes_wam/shoulder_pitch_link_fine.stl"/>
                </geometry>
            </visual>
            <inertial>
                <origin xyz="-.00236981 -.01542114 .03105614 " />
                <mass value="${3.87493756*0.1}" />
                <inertia
                    ixx="0.02140958"    ixy="-0.00002461"   ixz="0.00027172"
                                        iyy="0.015589060"   iyz="0.0018192"
                                                            izz="0.01377875" />
            </inertial>
            <collision>
                <geometry>
                    <mesh filename="${models_path}/meshes/meshes_wam/shoulder_pitch_link_convex.stl"/>
                </geometry>
            </collision>
        </link>
    </xacro:macro>

    <xacro:macro name="wam_upper_arm" params="prefix">
        <joint name="${prefix}/shoulder_yaw_joint" type="revolute">
            <parent link="${prefix}/shoulder_pitch_link"/>
            <child link="${prefix}/upper_arm_link"/>
            <origin xyz="0 0 0" rpy="${PI/2} 0 0"/>
            <axis xyz="0 0 1"/>
            <limit effort="${45*4}" lower="${-160.428 * M_PI / 180.0}" upper="${160.428 * M_PI / 180.0}" velocity="2.0"/>
            <dynamics damping="${1.5*b}" friction="0"/>
        </joint>
        <gazebo reference="${prefix}/shoulder_yaw_joint">
            <xacro:gz_joint/>
        </gazebo>
        <!-- <transmission name="${prefix}/shoulder_yaw_trans">
            <type>transmission_interface/SimpleTransmission</type>
            <joint name="${prefix}/shoulder_yaw_joint">
                <hardwareInterface>hardware_interface/VelocityJointInterface</hardwareInterface>
            </joint>
            <actuator name="${prefix}/shoulder_yaw_motor">
                <mechanicalReduction>1</mechanicalReduction>
            </actuator>
        </transmission> -->

        <link name="${prefix}/upper_arm_link" >
            <inertial>
                <origin xyz="0.00683258580000000 0.000033090000000 0.392492300000000" />
                <mass value="${2.20228141*0.1}" />
                <inertia
                    ixx=".05911077"     ixy="-0.00000738"   ixz="-0.00249612"
                                        iyy="0.05927043"    iyz="0.00001767"
                                                            izz="0.0032455" />
            </inertial>
            <visual>
                <material name="WAMGrey">
                    <color rgba="0.7 0.7 0.7 1.0"/>
                </material>
                <geometry>
                    <mesh filename="${models_path}/meshes/meshes_wam/upper_arm_link_fine.stl"/>
                </geometry>
            </visual>
            <collision>
                <geometry>
                    <mesh filename="${models_path}/meshes/meshes_wam/upper_arm_link_convex_decomposition_p1.stl"/>
                    <mesh filename="${models_path}/meshes/meshes_wam/upper_arm_link_convex_decomposition_p2.stl"/>
                </geometry>
            </collision>
        </link>
    </xacro:macro>

    <!-- Forearm macros -->
    <xacro:macro name="wam_forearm" params="prefix">
        <joint name="${prefix}/elbow_pitch_joint" type="revolute">
            <parent link="${prefix}/upper_arm_link"/>
            <child link="${prefix}/forearm_link"/>
            <origin xyz="0.045 0 0.55" rpy="${-PI/2} 0 0"/>
            <axis xyz="0 0 1"/>
            <limit effort="${30*4}" lower="${-51.567 * M_PI / 180.0}" upper="${180 * M_PI / 180.0}" velocity="2.00"/>
            <dynamics damping="${0.8*b}" friction="0"/>
        </joint>
        <gazebo reference="${prefix}/elbow_pitch_joint">
            <xacro:gz_joint/>
        </gazebo>
        <!-- <transmission name="${prefix}/elbow_pitch_trans">
            <type>transmission_interface/SimpleTransmission</type>
            <joint name="${prefix}/elbow_pitch_joint">
                <hardwareInterface>hardware_interface/VelocityJointInterface</hardwareInterface>
            </joint>
            <actuator name="${prefix}/elbow_pitch_motor">
                <mechanicalReduction>1</mechanicalReduction>
            </actuator>
        </transmission> -->
        <link name="${prefix}/forearm_link" >
            <inertial>
                <mass value="${0.50016804*0.1}" />
                <origin xyz="-0.04001488 -.14271662 -.00022942 " rpy="0 0 0" />
                <inertia
                    ixx="0.01491672"    ixy="0.001506040000000" ixz="0.000017410000000"
                                        iyy="0.002944630000000" iyz="0.000021090000000"
                                                                izz="0.014829880000000" />
            </inertial>
            <visual>
                <material name="WAMGrey">
                    <color rgba="0.7 0.7 0.7 1.0"/>
                </material>
                <geometry>
                    <mesh filename="${models_path}/meshes/meshes_wam/elbow_link_fine.stl"/>
                </geometry>
            </visual>
            <collision>
                <geometry>
                    <mesh filename="${models_path}/meshes/meshes_wam/elbow_link_convex.stl"/>
                </geometry>
            </collision>

            <visual>
                <material name="WAMGrey">
                    <color rgba="0.7 0.7 0.7 1.0"/>
                </material>
                <origin xyz="-0.045 -0.0730 0" rpy="${PI/2} 0 0" />
                <geometry>
                    <mesh filename="${models_path}/meshes/meshes_wam/forearm_link_fine.stl"/>
                </geometry>
            </visual>
            <collision>
                <origin xyz="-0.045 -0.0730 0" rpy="${PI/2} 0 0" />
                <geometry>
                    <mesh filename="${models_path}/meshes/meshes_wam/forearm_link_convex_decomposition_p1.stl"/>
                    <mesh filename="${models_path}/meshes/meshes_wam/forearm_link_convex_decomposition_p2.stl"/>
                </geometry>
            </collision>
        </link>
    </xacro:macro>

    <xacro:macro name="wam_wrist_yaw" params="prefix">
        <joint name="${prefix}/wrist_yaw_joint" type="revolute">
            <parent link="${prefix}/forearm_link"/>
            <child link="${prefix}/wrist_yaw_link"/>
            <origin xyz="-0.045 -0.3 0" rpy="${PI/2} 0 0"/>
            <axis xyz="0 0 1"/>
            <limit effort="${10*2}" lower="${-260.696 * M_PI / 180.0}" upper="${71.62 * M_PI / 180.0}" velocity="2.0"/>
            <dynamics damping="${0.5*b}" friction="0"/>
        </joint>
        <gazebo reference="${prefix}/wrist_yaw_joint">
            <xacro:gz_joint/>
        </gazebo>
        <!-- <transmission name="${prefix}/wrist_yaw_trans">
            <type>transmission_interface/SimpleTransmission</type>
            <joint name="${prefix}/wrist_yaw_joint">
                <hardwareInterface>hardware_interface/VelocityJointInterface</hardwareInterface>
            </joint>
            <actuator name="${prefix}/wrist_yaw_motor">
                <mechanicalReduction>1</mechanicalReduction>
            </actuator>
        </transmission> -->
        <link name="${prefix}/wrist_yaw_link" >
            <inertial>
                <origin xyz="0.00008921 0.00435824 -0.00511217 " />
                <mass value="${1.05376019*0.1}" />
                <inertia  ixx="0.00005029" ixy="0.00000020"  ixz="0.00007582"
                    iyy="0.00007582"  iyz="-0.00000359"
                    izz="0.00006270" />
            </inertial>
            <visual>
                <material name="WAMGrey">
                    <color rgba="0.7 0.7 0.7 1.0"/>
                </material>
                <origin xyz="0 0 0" rpy="0 0 0" />
                <geometry>
                    <mesh filename="${models_path}/meshes/meshes_wam/wrist_yaw_link_fine.stl"/>
                </geometry>
            </visual>
            <collision>
                <origin xyz="0 0 0" rpy="0 0 0" />
                <geometry>
                    <mesh filename="${models_path}/meshes/meshes_wam/wrist_yaw_link_convex_decomposition_p1.stl"/>
                    <mesh filename="${models_path}/meshes/meshes_wam/wrist_yaw_link_convex_decomposition_p2.stl"/>
                </geometry>
            </collision>
        </link>
    </xacro:macro>

    <xacro:macro name="wam_wrist_pitch" params="prefix">
        <joint name="${prefix}/wrist_pitch_joint" type="revolute">
            <parent link="${prefix}/wrist_yaw_link"/>
            <child link="${prefix}/wrist_pitch_link"/>
            <origin xyz="0 0 0" rpy="${-PI/2} 0 0"/>
            <axis xyz="0 0 1"/>
            <limit effort="${10*2}" lower="${-90 * M_PI / 180.0}" upper="${90 * M_PI / 180.0}" velocity="2.00"/>
            <dynamics damping="${0.1*b}" friction="0"/>
        </joint>
        <gazebo reference="${prefix}/wrist_pitch_joint">
            <xacro:gz_joint/>
        </gazebo>
        <!-- <transmission name="${prefix}/wrist_pitch_trans">
            <type>transmission_interface/SimpleTransmission</type>
            <joint name="${prefix}/wrist_pitch_joint">
                <hardwareInterface>hardware_interface/VelocityJointInterface</hardwareInterface>
            </joint>
            <actuator name="${prefix}/wrist_pitch_motor">
                <mechanicalReduction>1</mechanicalReduction>
            </actuator>
        </transmission> -->
        <link name="${prefix}/wrist_pitch_link" >
            <inertial>
                <origin xyz="-0.00012262 -0.02468336 -0.01703194 " rpy="0 0 0" />
                <mass value="${0.51797364*0.1}" />
                <inertia
                    ixx="0.00055516"  ixy="0.00000061"  ixz="-0.00000074"
                    iyy="0.00024367"  iyz="-0.00004590"
                    izz="0.00045358" />
            </inertial>
            <visual>
                <material name="WAMGrey">
                    <color rgba="0.7 0.7 0.7 1.0"/>
                </material>
                <geometry>
                    <mesh filename="${models_path}/meshes/meshes_wam/wrist_pitch_link_fine.stl"/>
                </geometry>
            </visual>
            <collision>
                <geometry>
                    <mesh filename="${models_path}/meshes/meshes_wam/wrist_pitch_link_convex_decomposition_p1.stl"/>
                    <mesh filename="${models_path}/meshes/meshes_wam/wrist_pitch_link_convex_decomposition_p2.stl"/>
                    <mesh filename="${models_path}/meshes/meshes_wam/wrist_pitch_link_convex_decomposition_p3.stl"/>
                </geometry>
            </collision>
        </link>
    </xacro:macro>

    <!-- Palm without force-torque sensor -->
    <xacro:macro name="wam_palm" params="prefix">
        <joint name="${prefix}/palm_yaw_joint" type="revolute">
            <parent link="${prefix}/wrist_pitch_link"/>
            <child link="${prefix}/wrist_palm_link"/>
            <origin xyz="0 0 0" rpy="${PI/2} 0 0"/>
            <axis xyz="0 0 1"/>
            <limit effort="${10*2}" lower="${-171.89 * M_PI / 180.0}" upper="${171.89 * M_PI / 180.0}" velocity="2.00"/>
            <!-- 2.95 is a limit taken in from 3 due to saftey and differences between arms. -->
            <dynamics damping="${0.1*b}" friction="0"/>
        </joint>
        <gazebo reference="${prefix}/palm_yaw_joint">
            <xacro:gz_joint/>
        </gazebo>
        <!-- <transmission name="${prefix}/palm_yaw_trans">
            <type>transmission_interface/SimpleTransmission</type>
            <joint name="${prefix}/palm_yaw_joint">
                <hardwareInterface>hardware_interface/VelocityJointInterface</hardwareInterface>
            </joint>
            <actuator name="${prefix}/palm_yaw_motor">
                <mechanicalReduction>1</mechanicalReduction>
            </actuator>
        </transmission> -->
        <link name="${prefix}/wrist_palm_link" >
            <inertial>
                <origin xyz="0.0 0.0 0.055" rpy="0 0 0" />
                <mass value="0.08286134" />
                <inertia  ixx="0.00010859" ixy="0.00000000"  ixz="-0.00000000"
                    iyy="0.00020683"  iyz="-0.0000000"
                    izz="0.00010851" />
            </inertial>
            <visual>
                <material name="WAMGrey">
                    <color rgba="0.7 0.7 0.7 1.0"/>
                </material>
                <origin xyz="0 0 0" rpy="0 0 0" />
                <geometry>
                    <mesh filename="${models_path}/meshes/meshes_wam/wrist_palm_link_fine.stl"/>
                </geometry>
            </visual>
            <collision>
                <origin xyz="0 0 0" rpy="0 0 0" />
                <geometry>
                    <mesh filename="${models_path}/meshes/meshes_wam/wrist_palm_link_convex.stl"/>
                </geometry>
            </collision>
        </link>
    </xacro:macro>

    <xacro:macro name="wam_wrist_palm_stump" params="prefix">
        <joint name="${prefix}/wrist_palm_stump_joint" type="fixed">
            <parent link="${prefix}/wrist_palm_link"/>
            <child link="${prefix}/wrist_palm_stump_link"/>
            <origin xyz="0 0 0.06" rpy="0 0 0"/>
        </joint>
        <link name="${prefix}/wrist_palm_stump_link" >
            <inertial>
                <mass value="0.000001" />
                <inertia
                    ixx="0.0000001" ixy="0.0" ixz="0.0"
                    iyy="0.0000001" iyz="0.0"
                    izz="0.0000001" />
            </inertial>
        </link>
    </xacro:macro>

    <!-- Palm with ForceTorque macros -->
    <xacro:macro name="wam_wrist_palm_torque_sensor" params="prefix">
        <joint name="${prefix}/wam_wrist_palm_torque_sensor_joint" type="fixed">
            <parent link="${prefix}/wrist_palm_link"/>
            <child link="${prefix}/wam_wrist_palm_torque_sensor_link"/>
            <origin xyz="0 0 0.06713340" rpy="0 0 0"/>
            <axis xyz="0 0 1"/>
            <limit effort="5" lower="-2.95" upper="2.95" velocity="0.20"/> <!--[> 2.95 is a limit taken in from 3 due to saftey and differences between arms. <]-->
                <!-- <safety_controller k_position="100" k_velocity="3" soft_lower_limit="-100.0" soft_upper_limit="100.0" /> <] -->
            <dynamics damping="0.1" friction="100.0"/>
        </joint>
        <link name="${prefix}/wam_wrist_palm_torque_sensor_link" >
            <inertial>
                <origin xyz="-0.00000134 -0.00228167 -0.00000141" rpy="0 0 0" />
                <mass value="0.17286134" />
                <inertia    ixx="0.00010859"    ixy="0.00000000"    ixz="-0.00000000"
                                                iyy="0.00020683"    iyz="-0.0000000"
                                                                    izz="0.00010851" />
            </inertial>
            <visual>
                <material name="WAMGrey">
                    <color rgba="0.7 0.7 0.7 1.0"/>
                </material>
                <origin xyz="0 0 0" rpy="0 0 0" />
                <geometry>
                    <mesh filename="${models_path}/meshes/meshes_wam/torque_sensor_plate.stl"/>
                </geometry>
            </visual>
            <collision>
                <origin xyz="0 0 0" rpy="0 0 0" />
                <geometry>
                    <mesh filename="${models_path}/meshes/meshes_wam/torque_sensor_plate.stl"/>
                </geometry>
            </collision>
        </link>
    </xacro:macro>

    <xacro:macro name="wam_stump" params="prefix">
        <joint name="${prefix}/elbow_pitch_joint" type="revolute">
            <parent link="${prefix}/upper_arm_link"/>
            <child link="${prefix}/stump_link"/>
            <origin xyz="0.045 0 0.55" rpy="${-PI/2} 0 0"/>
            <axis xyz="0 0 1"/>
            <limit effort="15" lower="-0.9" upper="${PI}" velocity="2.0"/>
            <dynamics damping="${0.1*b}" friction="0"/>
        </joint>
        <link name="${prefix}/stump_link" >
            <inertial>
                <mass value="0.408" />
                <origin xyz="-0.0195 -.02566 -.00022942 " rpy="0 0 0" />
                <inertia
                    ixx="0.01491672"    ixy="0.001506040000000" ixz="0.000017410000000"
                                        iyy="0.002944630000000" iyz="0.000021090000000"
                                                                izz="0.014829880000000" />
            </inertial>
            <visual>
                <material name="WAMGrey">
                    <color rgba="0.7 0.7 0.7 1.0"/>
                </material>
                <geometry>
                    <mesh filename="${models_path}/meshes/meshes_wam/elbow_link_fine.stl"/>
                </geometry>
            </visual>
            <collision>
                <geometry>
                    <mesh filename="${models_path}/meshes/meshes_wam/elbow_link_convex.stl"/>
                </geometry>
            </collision>
        </link>
    </xacro:macro>
</robot>
